Workbook

Sheet Dashboard
B2: IAS ELECTION CAMPAIGN — LIVE CONTACT DASHBOARD
B3: 1,873 members from the register dated 28/04/2026 · every figure recalculates as the team fills in column O of the Members sheet
B5: TOTAL MEMBERS | D5: CONTACTED | F5: POSITIVE | H5: TO FOLLOW UP | L5: BY EMIRATE
B6: =COUNTA(Members!$C$4:$C$1876) -> 1873 | D6: =COUNTA(Members!$O$4:$O$1876)-COUNTIF(Members!$O$4:$O$1876,"Not Contacted") -> 0 | F6: =COUNTIF(Members!$O$4:$O$1876,"Positive") -> 0 | H6: =COUNTIF(Members!$O$4:$O$1876,"To Be Followed Up") -> 0 | L6: Emirate | M6: Members | N6: Contacted | O6: Positive
B7: Contact rate | C7: =IFERROR((COUNTA(Members!$O$4:$O$1876)-COUNTIF(Members!$O$4:$O$1876,"Not Contacted"))/COUNTA(Members!$O$4:$O$1876),0) -> 0 | D7: Positive rate | E7: =IFERROR(COUNTIF(Members!$O$4:$O$1876,"Positive")/MAX(1,COUNTA(Members!$O$4:$O$1876)-COUNTIF(Members!$O$4:$O$1876,"Not Contacted")),0) -> 0 | F7: Negative | G7: =COUNTIF(Members!$O$4:$O$1876,"Negative") -> 0 | H7: Still to call | I7: =COUNTIF(Members!$O$4:$O$1876,"Not Contacted") -> 1873 | L7: Sharjah | M7: =COUNTIF(Members!$J$4:$J$1876,$L7) -> 979 | N7: =M7-COUNTIFS(Members!$J$4:$J$1876,$L7,Members!$O$4:$O$1876,"Not Contacted") -> 0 | O7: =COUNTIFS(Members!$J$4:$J$1876,$L7,Members!$O$4:$O$1876,"Positive") -> 0
L8: Dubai | M8: =COUNTIF(Members!$J$4:$J$1876,$L8) -> 532 | N8: =M8-COUNTIFS(Members!$J$4:$J$1876,$L8,Members!$O$4:$O$1876,"Not Contacted") -> 0 | O8: =COUNTIFS(Members!$J$4:$J$1876,$L8,Members!$O$4:$O$1876,"Positive") -> 0
B9: RESPONSE BREAKDOWN | L9: Ajman | M9: =COUNTIF(Members!$J$4:$J$1876,$L9) -> 128 | N9: =M9-COUNTIFS(Members!$J$4:$J$1876,$L9,Members!$O$4:$O$1876,"Not Contacted") -> 0 | O9: =COUNTIFS(Members!$J$4:$J$1876,$L9,Members!$O$4:$O$1876,"Positive") -> 0
B10: Call status | C10: Members | D10: Share | E10: Progress | L10: Abu Dhabi | M10: =COUNTIF(Members!$J$4:$J$1876,$L10) -> 25 | N10: =M10-COUNTIFS(Members!$J$4:$J$1876,$L10,Members!$O$4:$O$1876,"Not Contacted") -> 0 | O10: =COUNTIFS(Members!$J$4:$J$1876,$L10,Members!$O$4:$O$1876,"Positive") -> 0
B11: Not Contacted | C11: =COUNTIF(Members!$O$4:$O$1876,B11) -> 1873 | D11: =IFERROR(C11/$B$6,0) -> 1 | E11: =C11 -> 1873 | L11: Umm Al Quwain | M11: =COUNTIF(Members!$J$4:$J$1876,$L11) -> 15 | N11: =M11-COUNTIFS(Members!$J$4:$J$1876,$L11,Members!$O$4:$O$1876,"Not Contacted") -> 0 | O11: =COUNTIFS(Members!$J$4:$J$1876,$L11,Members!$O$4:$O$1876,"Positive") -> 0
B12: Positive | C12: =COUNTIF(Members!$O$4:$O$1876,B12) -> 0 | D12: =IFERROR(C12/$B$6,0) -> 0 | E12: =C12 -> 0 | L12: Ras Al Khaimah | M12: =COUNTIF(Members!$J$4:$J$1876,$L12) -> 10 | N12: =M12-COUNTIFS(Members!$J$4:$J$1876,$L12,Members!$O$4:$O$1876,"Not Contacted") -> 0 | O12: =COUNTIFS(Members!$J$4:$J$1876,$L12,Members!$O$4:$O$1876,"Positive") -> 0
B13: To Be Followed Up | C13: =COUNTIF(Members!$O$4:$O$1876,B13) -> 0 | D13: =IFERROR(C13/$B$6,0) -> 0 | E13: =C13 -> 0 | L13: Fujairah | M13: =COUNTIF(Members!$J$4:$J$1876,$L13) -> 4 | N13: =M13-COUNTIFS(Members!$J$4:$J$1876,$L13,Members!$O$4:$O$1876,"Not Contacted") -> 0 | O13: =COUNTIFS(Members!$J$4:$J$1876,$L13,Members!$O$4:$O$1876,"Positive") -> 0
B14: Undecided | C14: =COUNTIF(Members!$O$4:$O$1876,B14) -> 0 | D14: =IFERROR(C14/$B$6,0) -> 0 | E14: =C14 -> 0 | L14: Not recorded | M14: =$B$6-SUM(M7:M13) -> 180
B15: Negative | C15: =COUNTIF(Members!$O$4:$O$1876,B15) -> 0 | D15: =IFERROR(C15/$B$6,0) -> 0 | E15: =C15 -> 0
B16: Unreachable | C16: =COUNTIF(Members!$O$4:$O$1876,B16) -> 0 | D16: =IFERROR(C16/$B$6,0) -> 0 | E16: =C16 -> 0 | L16: BY CALLER
B17: Not Eligible / Inactive | C17: =COUNTIF(Members!$O$4:$O$1876,B17) -> 0 | D17: =IFERROR(C17/$B$6,0) -> 0 | E17: =C17 -> 0 | L17: Assigned to | M17: Assigned | N17: Done | O17: Positive
B18: TOTAL | C18: =SUM(C11:C17) -> 1873 | D18: =IFERROR(C18/$B$6,0) -> 1 | L18: =Lists!C2 -> Unassigned | M18: =COUNTIF(Members!$P$4:$P$1876,$L18) -> 1873 | N18: =M18-COUNTIFS(Members!$P$4:$P$1876,$L18,Members!$O$4:$O$1876,"Not Contacted") -> 0 | O18: =COUNTIFS(Members!$P$4:$P$1876,$L18,Members!$O$4:$O$1876,"Positive") -> 0
L19: =Lists!C3 -> Volunteer 1 | M19: =COUNTIF(Members!$P$4:$P$1876,$L19) -> 0 | N19: =M19-COUNTIFS(Members!$P$4:$P$1876,$L19,Members!$O$4:$O$1876,"Not Contacted") -> 0 | O19: =COUNTIFS(Members!$P$4:$P$1876,$L19,Members!$O$4:$O$1876,"Positive") -> 0
L20: =Lists!C4 -> Volunteer 2 | M20: =COUNTIF(Members!$P$4:$P$1876,$L20) -> 0 | N20: =M20-COUNTIFS(Members!$P$4:$P$1876,$L20,Members!$O$4:$O$1876,"Not Contacted") -> 0 | O20: =COUNTIFS(Members!$P$4:$P$1876,$L20,Members!$O$4:$O$1876,"Positive") -> 0
B21: BY HOME DISTRICT IN KERALA | L21: =Lists!C5 -> Volunteer 3 | M21: =COUNTIF(Members!$P$4:$P$1876,$L21) -> 0 | N21: =M21-COUNTIFS(Members!$P$4:$P$1876,$L21,Members!$O$4:$O$1876,"Not Contacted") -> 0 | O21: =COUNTIFS(Members!$P$4:$P$1876,$L21,Members!$O$4:$O$1876,"Positive") -> 0
B22: District | C22: Members | D22: Contacted | E22: Positive | F22: Follow up | G22: Negative | H22: Not called | I22: % contacted | J22: % positive | L22: =Lists!C6 -> Volunteer 4 | M22: =COUNTIF(Members!$P$4:$P$1876,$L22) -> 0 | N22: =M22-COUNTIFS(Members!$P$4:$P$1876,$L22,Members!$O$4:$O$1876,"Not Contacted") -> 0 | O22: =COUNTIFS(Members!$P$4:$P$1876,$L22,Members!$O$4:$O$1876,"Positive") -> 0
B23: Alappuzha | C23: =COUNTIF(Members!$L$4:$L$1876,$B23) -> 110 | D23: =C23-H23 -> 0 | E23: =COUNTIFS(Members!$L$4:$L$1876,$B23,Members!$O$4:$O$1876,"Positive") -> 0 | F23: =COUNTIFS(Members!$L$4:$L$1876,$B23,Members!$O$4:$O$1876,"To Be Followed Up") -> 0 | G23: =COUNTIFS(Members!$L$4:$L$1876,$B23,Members!$O$4:$O$1876,"Negative") -> 0 | H23: =COUNTIFS(Members!$L$4:$L$1876,$B23,Members!$O$4:$O$1876,"Not Contacted") -> 110 | I23: =IFERROR(D23/C23,0) -> 0 | J23: =IFERROR(E23/MAX(1,D23),0) -> 0 | L23: =Lists!C7 -> Volunteer 5 | M23: =COUNTIF(Members!$P$4:$P$1876,$L23) -> 0 | N23: =M23-COUNTIFS(Members!$P$4:$P$1876,$L23,Members!$O$4:$O$1876,"Not Contacted") -> 0 | O23: =COUNTIFS(Members!$P$4:$P$1876,$L23,Members!$O$4:$O$1876,"Positive") -> 0
B24: Ernakulam | C24: =COUNTIF(Members!$L$4:$L$1876,$B24) -> 64 | D24: =C24-H24 -> 0 | E24: =COUNTIFS(Members!$L$4:$L$1876,$B24,Members!$O$4:$O$1876,"Positive") -> 0 | F24: =COUNTIFS(Members!$L$4:$L$1876,$B24,Members!$O$4:$O$1876,"To Be Followed Up") -> 0 | G24: =COUNTIFS(Members!$L$4:$L$1876,$B24,Members!$O$4:$O$1876,"Negative") -> 0 | H24: =COUNTIFS(Members!$L$4:$L$1876,$B24,Members!$O$4:$O$1876,"Not Contacted") -> 64 | I24: =IFERROR(D24/C24,0) -> 0 | J24: =IFERROR(E24/MAX(1,D24),0) -> 0 | L24: =Lists!C8 -> Volunteer 6 | M24: =COUNTIF(Members!$P$4:$P$1876,$L24) -> 0 | N24: =M24-COUNTIFS(Members!$P$4:$P$1876,$L24,Members!$O$4:$O$1876,"Not Contacted") -> 0 | O24: =COUNTIFS(Members!$P$4:$P$1876,$L24,Members!$O$4:$O$1876,"Positive") -> 0
B25: Idukki | C25: =COUNTIF(Members!$L$4:$L$1876,$B25) -> 4 | D25: =C25-H25 -> 0 | E25: =COUNTIFS(Members!$L$4:$L$1876,$B25,Members!$O$4:$O$1876,"Positive") -> 0 | F25: =COUNTIFS(Members!$L$4:$L$1876,$B25,Members!$O$4:$O$1876,"To Be Followed Up") -> 0 | G25: =COUNTIFS(Members!$L$4:$L$1876,$B25,Members!$O$4:$O$1876,"Negative") -> 0 | H25: =COUNTIFS(Members!$L$4:$L$1876,$B25,Members!$O$4:$O$1876,"Not Contacted") -> 4 | I25: =IFERROR(D25/C25,0) -> 0 | J25: =IFERROR(E25/MAX(1,D25),0) -> 0 | L25: =Lists!C9 -> Volunteer 7 | M25: =COUNTIF(Members!$P$4:$P$1876,$L25) -> 0 | N25: =M25-COUNTIFS(Members!$P$4:$P$1876,$L25,Members!$O$4:$O$1876,"Not Contacted") -> 0 | O25: =COUNTIFS(Members!$P$4:$P$1876,$L25,Members!$O$4:$O$1876,"Positive") -> 0
B26: Kannur | C26: =COUNTIF(Members!$L$4:$L$1876,$B26) -> 191 | D26: =C26-H26 -> 0 | E26: =COUNTIFS(Members!$L$4:$L$1876,$B26,Members!$O$4:$O$1876,"Positive") -> 0 | F26: =COUNTIFS(Members!$L$4:$L$1876,$B26,Members!$O$4:$O$1876,"To Be Followed Up") -> 0 | G26: =COUNTIFS(Members!$L$4:$L$1876,$B26,Members!$O$4:$O$1876,"Negative") -> 0 | H26: =COUNTIFS(Members!$L$4:$L$1876,$B26,Members!$O$4:$O$1876,"Not Contacted") -> 191 | I26: =IFERROR(D26/C26,0) -> 0 | J26: =IFERROR(E26/MAX(1,D26),0) -> 0 | L26: =Lists!C10 -> Volunteer 8 | M26: =COUNTIF(Members!$P$4:$P$1876,$L26) -> 0 | N26: =M26-COUNTIFS(Members!$P$4:$P$1876,$L26,Members!$O$4:$O$1876,"Not Contacted") -> 0 | O26: =COUNTIFS(Members!$P$4:$P$1876,$L26,Members!$O$4:$O$1876,"Positive") -> 0
B27: Kasaragod | C27: =COUNTIF(Members!$L$4:$L$1876,$B27) -> 276 | D27: =C27-H27 -> 0 | E27: =COUNTIFS(Members!$L$4:$L$1876,$B27,Members!$O$4:$O$1876,"Positive") -> 0 | F27: =COUNTIFS(Members!$L$4:$L$1876,$B27,Members!$O$4:$O$1876,"To Be Followed Up") -> 0 | G27: =COUNTIFS(Members!$L$4:$L$1876,$B27,Members!$O$4:$O$1876,"Negative") -> 0 | H27: =COUNTIFS(Members!$L$4:$L$1876,$B27,Members!$O$4:$O$1876,"Not Contacted") -> 276 | I27: =IFERROR(D27/C27,0) -> 0 | J27: =IFERROR(E27/MAX(1,D27),0) -> 0 | L27: =Lists!C11 -> Volunteer 9 | M27: =COUNTIF(Members!$P$4:$P$1876,$L27) -> 0 | N27: =M27-COUNTIFS(Members!$P$4:$P$1876,$L27,Members!$O$4:$O$1876,"Not Contacted") -> 0 | O27: =COUNTIFS(Members!$P$4:$P$1876,$L27,Members!$O$4:$O$1876,"Positive") -> 0
B28: Kollam | C28: =COUNTIF(Members!$L$4:$L$1876,$B28) -> 137 | D28: =C28-H28 -> 0 | E28: =COUNTIFS(Members!$L$4:$L$1876,$B28,Members!$O$4:$O$1876,"Positive") -> 0 | F28: =COUNTIFS(Members!$L$4:$L$1876,$B28,Members!$O$4:$O$1876,"To Be Followed Up") -> 0 | G28: =COUNTIFS(Members!$L$4:$L$1876,$B28,Members!$O$4:$O$1876,"Negative") -> 0 | H28: =COUNTIFS(Members!$L$4:$L$1876,$B28,Members!$O$4:$O$1876,"Not Contacted") -> 137 | I28: =IFERROR(D28/C28,0) -> 0 | J28: =IFERROR(E28/MAX(1,D28),0) -> 0 | L28: =Lists!C12 -> Volunteer 10 | M28: =COUNTIF(Members!$P$4:$P$1876,$L28) -> 0 | N28: =M28-COUNTIFS(Members!$P$4:$P$1876,$L28,Members!$O$4:$O$1876,"Not Contacted") -> 0 | O28: =COUNTIFS(Members!$P$4:$P$1876,$L28,Members!$O$4:$O$1876,"Positive") -> 0
B29: Kottayam | C29: =COUNTIF(Members!$L$4:$L$1876,$B29) -> 44 | D29: =C29-H29 -> 0 | E29: =COUNTIFS(Members!$L$4:$L$1876,$B29,Members!$O$4:$O$1876,"Positive") -> 0 | F29: =COUNTIFS(Members!$L$4:$L$1876,$B29,Members!$O$4:$O$1876,"To Be Followed Up") -> 0 | G29: =COUNTIFS(Members!$L$4:$L$1876,$B29,Members!$O$4:$O$1876,"Negative") -> 0 | H29: =COUNTIFS(Members!$L$4:$L$1876,$B29,Members!$O$4:$O$1876,"Not Contacted") -> 44 | I29: =IFERROR(D29/C29,0) -> 0 | J29: =IFERROR(E29/MAX(1,D29),0) -> 0 | L29: =Lists!C13 -> Volunteer 11 | M29: =COUNTIF(Members!$P$4:$P$1876,$L29) -> 0 | N29: =M29-COUNTIFS(Members!$P$4:$P$1876,$L29,Members!$O$4:$O$1876,"Not Contacted") -> 0 | O29: =COUNTIFS(Members!$P$4:$P$1876,$L29,Members!$O$4:$O$1876,"Positive") -> 0
B30: Kozhikode | C30: =COUNTIF(Members!$L$4:$L$1876,$B30) -> 87 | D30: =C30-H30 -> 0 | E30: =COUNTIFS(Members!$L$4:$L$1876,$B30,Members!$O$4:$O$1876,"Positive") -> 0 | F30: =COUNTIFS(Members!$L$4:$L$1876,$B30,Members!$O$4:$O$1876,"To Be Followed Up") -> 0 | G30: =COUNTIFS(Members!$L$4:$L$1876,$B30,Members!$O$4:$O$1876,"Negative") -> 0 | H30: =COUNTIFS(Members!$L$4:$L$1876,$B30,Members!$O$4:$O$1876,"Not Contacted") -> 87 | I30: =IFERROR(D30/C30,0) -> 0 | J30: =IFERROR(E30/MAX(1,D30),0) -> 0 | L30: =Lists!C14 -> Volunteer 12 | M30: =COUNTIF(Members!$P$4:$P$1876,$L30) -> 0 | N30: =M30-COUNTIFS(Members!$P$4:$P$1876,$L30,Members!$O$4:$O$1876,"Not Contacted") -> 0 | O30: =COUNTIFS(Members!$P$4:$P$1876,$L30,Members!$O$4:$O$1876,"Positive") -> 0
B31: Malappuram | C31: =COUNTIF(Members!$L$4:$L$1876,$B31) -> 125 | D31: =C31-H31 -> 0 | E31: =COUNTIFS(Members!$L$4:$L$1876,$B31,Members!$O$4:$O$1876,"Positive") -> 0 | F31: =COUNTIFS(Members!$L$4:$L$1876,$B31,Members!$O$4:$O$1876,"To Be Followed Up") -> 0 | G31: =COUNTIFS(Members!$L$4:$L$1876,$B31,Members!$O$4:$O$1876,"Negative") -> 0 | H31: =COUNTIFS(Members!$L$4:$L$1876,$B31,Members!$O$4:$O$1876,"Not Contacted") -> 125 | I31: =IFERROR(D31/C31,0) -> 0 | J31: =IFERROR(E31/MAX(1,D31),0) -> 0
B32: Palakkad | C32: =COUNTIF(Members!$L$4:$L$1876,$B32) -> 38 | D32: =C32-H32 -> 0 | E32: =COUNTIFS(Members!$L$4:$L$1876,$B32,Members!$O$4:$O$1876,"Positive") -> 0 | F32: =COUNTIFS(Members!$L$4:$L$1876,$B32,Members!$O$4:$O$1876,"To Be Followed Up") -> 0 | G32: =COUNTIFS(Members!$L$4:$L$1876,$B32,Members!$O$4:$O$1876,"Negative") -> 0 | H32: =COUNTIFS(Members!$L$4:$L$1876,$B32,Members!$O$4:$O$1876,"Not Contacted") -> 38 | I32: =IFERROR(D32/C32,0) -> 0 | J32: =IFERROR(E32/MAX(1,D32),0) -> 0
B33: Pathanamthitta | C33: =COUNTIF(Members!$L$4:$L$1876,$B33) -> 165 | D33: =C33-H33 -> 0 | E33: =COUNTIFS(Members!$L$4:$L$1876,$B33,Members!$O$4:$O$1876,"Positive") -> 0 | F33: =COUNTIFS(Members!$L$4:$L$1876,$B33,Members!$O$4:$O$1876,"To Be Followed Up") -> 0 | G33: =COUNTIFS(Members!$L$4:$L$1876,$B33,Members!$O$4:$O$1876,"Negative") -> 0 | H33: =COUNTIFS(Members!$L$4:$L$1876,$B33,Members!$O$4:$O$1876,"Not Contacted") -> 165 | I33: =IFERROR(D33/C33,0) -> 0 | J33: =IFERROR(E33/MAX(1,D33),0) -> 0
B34: Thiruvananthapuram | C34: =COUNTIF(Members!$L$4:$L$1876,$B34) -> 139 | D34: =C34-H34 -> 0 | E34: =COUNTIFS(Members!$L$4:$L$1876,$B34,Members!$O$4:$O$1876,"Positive") -> 0 | F34: =COUNTIFS(Members!$L$4:$L$1876,$B34,Members!$O$4:$O$1876,"To Be Followed Up") -> 0 | G34: =COUNTIFS(Members!$L$4:$L$1876,$B34,Members!$O$4:$O$1876,"Negative") -> 0 | H34: =COUNTIFS(Members!$L$4:$L$1876,$B34,Members!$O$4:$O$1876,"Not Contacted") -> 139 | I34: =IFERROR(D34/C34,0) -> 0 | J34: =IFERROR(E34/MAX(1,D34),0) -> 0
B35: Thrissur | C35: =COUNTIF(Members!$L$4:$L$1876,$B35) -> 348 | D35: =C35-H35 -> 0 | E35: =COUNTIFS(Members!$L$4:$L$1876,$B35,Members!$O$4:$O$1876,"Positive") -> 0 | F35: =COUNTIFS(Members!$L$4:$L$1876,$B35,Members!$O$4:$O$1876,"To Be Followed Up") -> 0 | G35: =COUNTIFS(Members!$L$4:$L$1876,$B35,Members!$O$4:$O$1876,"Negative") -> 0 | H35: =COUNTIFS(Members!$L$4:$L$1876,$B35,Members!$O$4:$O$1876,"Not Contacted") -> 348 | I35: =IFERROR(D35/C35,0) -> 0 | J35: =IFERROR(E35/MAX(1,D35),0) -> 0
B36: Wayanad | C36: =COUNTIF(Members!$L$4:$L$1876,$B36) -> 4 | D36: =C36-H36 -> 0 | E36: =COUNTIFS(Members!$L$4:$L$1876,$B36,Members!$O$4:$O$1876,"Positive") -> 0 | F36: =COUNTIFS(Members!$L$4:$L$1876,$B36,Members!$O$4:$O$1876,"To Be Followed Up") -> 0 | G36: =COUNTIFS(Members!$L$4:$L$1876,$B36,Members!$O$4:$O$1876,"Negative") -> 0 | H36: =COUNTIFS(Members!$L$4:$L$1876,$B36,Members!$O$4:$O$1876,"Not Contacted") -> 4 | I36: =IFERROR(D36/C36,0) -> 0 | J36: =IFERROR(E36/MAX(1,D36),0) -> 0
B37: Outside Kerala | C37: =COUNTIF(Members!$L$4:$L$1876,$B37) -> 26 | D37: =C37-H37 -> 0 | E37: =COUNTIFS(Members!$L$4:$L$1876,$B37,Members!$O$4:$O$1876,"Positive") -> 0 | F37: =COUNTIFS(Members!$L$4:$L$1876,$B37,Members!$O$4:$O$1876,"To Be Followed Up") -> 0 | G37: =COUNTIFS(Members!$L$4:$L$1876,$B37,Members!$O$4:$O$1876,"Negative") -> 0 | H37: =COUNTIFS(Members!$L$4:$L$1876,$B37,Members!$O$4:$O$1876,"Not Contacted") -> 26 | I37: =IFERROR(D37/C37,0) -> 0 | J37: =IFERROR(E37/MAX(1,D37),0) -> 0
B38: Unmatched — check | C38: =COUNTIF(Members!$L$4:$L$1876,$B38) -> 115 | D38: =C38-H38 -> 0 | E38: =COUNTIFS(Members!$L$4:$L$1876,$B38,Members!$O$4:$O$1876,"Positive") -> 0 | F38: =COUNTIFS(Members!$L$4:$L$1876,$B38,Members!$O$4:$O$1876,"To Be Followed Up") -> 0 | G38: =COUNTIFS(Members!$L$4:$L$1876,$B38,Members!$O$4:$O$1876,"Negative") -> 0 | H38: =COUNTIFS(Members!$L$4:$L$1876,$B38,Members!$O$4:$O$1876,"Not Contacted") -> 115 | I38: =IFERROR(D38/C38,0) -> 0 | J38: =IFERROR(E38/MAX(1,D38),0) -> 0
B39: TOTAL | C39: =SUM(C23:C38) -> 1873 | D39: =SUM(D23:D38) -> 0 | E39: =SUM(E23:E38) -> 0 | F39: =SUM(F23:F38) -> 0 | G39: =SUM(G23:G38) -> 0 | H39: =SUM(H23:H38) -> 1873 | I39: =IFERROR(D39/C39,0) -> 0 | J39: =IFERROR(E39/MAX(1,D39),0) -> 0
L42: HOW TO USE THIS WORKBOOK
L43: 1. | M43: Open the Members sheet. Filter column L (District) or column J (Emirate) to split the list between callers.
L44: 2. | M44: Set column P (Assigned To) for each block. Rename the volunteers on the Lists sheet first.
...

Sheet Members
A1: INDIAN ASSOCIATION SHARJAH | ELECTION CAMPAIGN — MEMBER CONTACT REGISTER
A2: Columns A–N are extracted from the membership PDF — do not edit. Columns O–T (shaded) are for the campaign team to fill in. Every entry updates the Dashboard automatically.
A3: S.No | B3: IAS ID | C3: Member Name | D3: Type | E3: Date of Birth | F3: Age | G3: Mobile (UAE) | H3: Phone (India) | I3: Email | J3: Emirate | K3: Place / Address | L3: District | M3: Blood Grp | N3: Member Since | O3: Call Status | P3: Assigned To | Q3: Contact Date | R3: Contact Method | S3: Next Follow-up | T3: Remarks
A4: 1 | B4: 19 | C4: GEORGE K.T. | D4: L | E4: 13793 | F4: =IFERROR(DATEDIF(E4,TODAY(),"Y"),"") -> 88 | G4: 0506464369 | H4: 5413320471 | J4: Sharjah | K4: T.C.3/1004, OPPOSITE HOLY CROSS, CHURCH, MUTTADA, TRIVANDRUM | L4: Thiruvananthapuram | M4: B+ | N4: 30740 | O4: Not Contacted | P4: Unassigned
A5: 2 | B5: 32 | C5: KASIM KUNJU M.M. | D5: L | E5: 16929 | F5: =IFERROR(DATEDIF(E5,TODAY(),"Y"),"") -> 80 | G5: 0504817685 | H5: 4702692004 | I5: kassim@binmalik.ae | J5: Sharjah | K5: K.V.P.HOUSE, PERROR.PO,KILIMANOOR, TRIVANDRUM DISTRICT, KERALA | L5: Thiruvananthapuram | N5: 30849 | O5: Not Contacted | P5: Unassigned
A6: 3 | B6: 37 | C6: NAVINCHANDRA NARAINDAS RAIPANCHO L I LAL | D6: L | E6: 15269 | F6: =IFERROR(DATEDIF(E6,TODAY(),"Y"),"") -> 84 | G6: 0506324580 | H6: 9869770775 | J6: Sharjah | K6: RAMCHANDRA LANE, S.C.MALAD, BOMBAY. | L6: Outside Kerala | N6: 29108 | O6: Not Contacted | P6: Unassigned
A7: 4 | B7: 63 | C7: SHAMSUDHEEN K.V. | D7: L | E7: 16844 | F7: =IFERROR(DATEDIF(E7,TODAY(),"Y"),"") -> 80 | G7: 0506467801 | H7: 9745131310 | I7: kvshams@gmail.com | J7: Sharjah | K7: GLANDALE POINT, 7C-6/235 G3, BANK STREET, CALICUT-673001 | L7: Kozhikode | M7: O+ | N7: 28967 | O7: Not Contacted | P7: Unassigned
A8: 5 | B8: 87 | C8: Adv. Y.A.RAHIM | D8: L | E8: 21141 | F8: =IFERROR(DATEDIF(E8,TODAY(),"Y"),"") -> 68 | G8: 0506320994 | H8: 471433316 | I8: adv.yarahim@gmail.com | J8: Sharjah | K8: T.C.5/1568 AMBALAMUKKU, KOWDIAR, TRIVANDRUM DISTRICT, KERALA | L8: Thiruvananthapuram | N8: 32553 | O8: Not Contacted | P8: Unassigned
A9: 6 | B9: 101 | C9: MOHAMMEDUNNI M.C. | D9: L | E9: 20920 | F9: =IFERROR(DATEDIF(E9,TODAY(),"Y"),"") -> 69 | G9: 0506460753 | I9: indane2016@gmail.com | J9: Ajman | K9: MANALATHU VALAPPIL HOUSE,, POST CHALISSERY, PALAKKAD, 00914662256119 | L9: Palakkad | M9: B+ | N9: 32559 | O9: Not Contacted | P9: Unassigned
A10: 7 | B10: 105 | C10: MOIDUNNI K. | D10: L | E10: 19998 | F10: =IFERROR(DATEDIF(E10,TODAY(),"Y"),"") -> 71 | G10: 0504630151 | H10: 494681354 | J10: Sharjah | K10: KALAKKAT HOUSE, EDAPPAL CHUNGAM, SUKAPURAM POST, MALAPPURAM | L10: Malappuram | N10: 32554 | O10: Not Contacted | P10: Unassigned
A11: 8 | B11: 109 | C11: V.T.JACOB | D11: L | E11: 18970 | F11: =IFERROR(DATEDIF(E11,TODAY(),"Y"),"") -> 74 | G11: 0507977146 | H11: 4885242208 | I11: jacob.vazhappilly@oce.ae | J11: Ajman | K11: VAZHAPPILLY HOUSE, ERANELLUR POST, VIA KECHERY, TRICHUR DISTRICT | L11: Thrissur | M11: O+ | N11: 31349 | O11: Not Contacted | P11: Unassigned
A12: 9 | B12: 110 | C12: N.ABDUL KADER | D12: L | E12: 17349 | F12: =IFERROR(DATEDIF(E12,TODAY(),"Y"),"") -> 79 | G12: 0504974412 | H12: 4942440756 | I12: nabdulkader@crescent.ae | J12: Sharjah | K12: NALAKATH HOUSE, MOOLAKKAL, POST K-PURAM, VIA TANALUR-676307 | L12: Unmatched — check | N12: 30702 | O12: Not Contacted | P12: Unassigned
A13: 10 | B13: 111 | C13: TEL (O): 600548888 | D13: EXT | E13: 22042 | F13: =IFERROR(DATEDIF(E13,TODAY(),"Y"),"") -> 66 | G13: 0507000205 | H13: 9895557000 | I13: bash@safetymarine.com | K13: PADIYATH PARAVANNUR,PO.KALPAKANCHERY, MALAPPURAM DT, KERALA | L13: Malappuram | N13: 40988 | O13: Not Contacted | P13: Unassigned
A14: 11 | B14: 117 | C14: VARGHESE T.V. | D14: L | E14: 20586 | F14: =IFERROR(DATEDIF(E14,TODAY(),"Y"),"") -> 70 | G14: 0566727011 | H14: 485959140 | J14: Sharjah | K14: THOTTANKARA HOUSE, CHERANALLOOR, PERUMBAVOOR-683544, ERNAKULAM | L14: Ernakulam | N14: 32555 | O14: Not Contacted | P14: Unassigned
A15: 12 | B15: 126 | C15: YOUSEPH SAGHEER K.S. | D15: L | E15: 21112 | F15: =IFERROR(DATEDIF(E15,TODAY(),"Y"),"") -> 68 | G15: 0506287595 | I15: yousephsageer@gmail.com | J15: Sharjah | K15: KAKKASSERY HOUSE, MATHILAKAM, POST, TRICHUR DISTRICT, KERALA, 0091 9744287595 | L15: Thrissur | M15: O+ | N15: 30706 | O15: Not Contacted | P15: Unassigned
A16: 13 | B16: 129 | C16: SUBHAS CHANDRABOSE .P.V. | D16: L | E16: 20055 | F16: =IFERROR(DATEDIF(E16,TODAY(),"Y"),"") -> 71 | G16: 0507967459 | I16: shyamsubash@yahoo.com | J16: Dubai | K16: PARAMEL HOUSE, POST ADAT, TRICHUR, ,KERALA STATE., 0091 9846 447755 | L16: Thrissur | M16: O+ | N16: 30853 | O16: Not Contacted | P16: Unassigned
A17: 14 | B17: 136 | C17: MOHAMMED JALEEL .M.C. | D17: L | E17: 22063 | F17: =IFERROR(DATEDIF(E17,TODAY(),"Y"),"") -> 66 | G17: 0506526385 | H17: 91490332696 | I17: jaleelmcm60@gmail.com | J17: Dubai | K17: 'SANTHOSH', POST PERINGADI, NEW MAHE, KERALA. | L17: Kannur | M17: O+ | N17: 32554 | O17: Not Contacted | P17: Unassigned
A18: 15 | B18: 141 | C18: MANOHARAN .V. | D18: L | E18: 19343 | F18: =IFERROR(DATEDIF(E18,TODAY(),"Y"),"") -> 73 | G18: 0557661249 | H18: 4972860383 | I18: m.velutheri@gmail.com | J18: Sharjah | K18: VELUTHERI HOUSE, KATTAMPALLY, POST, KANNUR DISTRICT, KERALA | L18: Kannur | M18: O+ | N18: 32557 | O18: Not Contacted | P18: Unassigned
A19: 16 | B19: 160 | C19: JACOB GEORGE | D19: L | E19: 20033 | F19: =IFERROR(DATEDIF(E19,TODAY(),"Y"),"") -> 71 | G19: 0506348037 | H19: 4735227453 | I19: mushiraf@emirates.net.ae | J19: Sharjah | K19: KANJIKUZHIYIL HOUSE, THEKKEPURAM, RANNY POST, PATHANAMTHITTA | L19: Pathanamthitta | M19: A+ | N19: 32558 | O19: Not Contacted | P19: Unassigned
A20: 17 | B20: 163 | C20: SIVANKUTTY NAIR P.R. | D20: L | E20: 18752 | F20: =IFERROR(DATEDIF(E20,TODAY(),"Y"),"") -> 75 | G20: 0506267142 | I20: novelemllc@yahoo.com | J20: Sharjah | K20: FLAT NO, C 2 bHAGEERATHA APARTMENT kANJIRAMPARA P, VATTIYOORKAVU,TRIVANDRUM DT | L20: Thiruvananthapuram | M20: A+ | N20: 32551 | O20: Not Contacted | P20: Unassigned
A21: 18 | B21: 164 | C21: UNNIKRISHNAN M. | D21: L | E21: 19419 | F21: =IFERROR(DATEDIF(E21,TODAY(),"Y"),"") -> 73 | G21: 0506790491 | J21: Ajman | K21: KALLARMANGALAM POST, VIA, KADAMPUZHA, MALAPPURAM DISTRICT, 0091-494 -61014 | L21: Malappuram | M21: O+ | N21: 32540 | O21: Not Contacted | P21: Unassigned
A22: 19 | B22: 165 | C22: JOSE K.K. | D22: L | E22: 14389 | F22: =IFERROR(DATEDIF(E22,TODAY(),"Y"),"") -> 87 | G22: 0501859931 | H22: 42322311279487872123 | I22: kkjose39@yahoo.com | J22: Sharjah | K22: HIGH FIELD COTTAGE#26, HIGH FIELD - COONOOR-643101, NILGIRIS DISTRICT | L22: Unmatched — check | M22: AB- | N22: 32555 | O22: Not Contacted | P22: Unassigned
A23: 20 | B23: 169 | C23: SADANANDAN T. K. | D23: L | E23: 18763 | F23: =IFERROR(DATEDIF(E23,TODAY(),"Y"),"") -> 75 | G23: 0506461680 | H23: 9446125437 | I23: sadantk@hotmail.com | J23: Sharjah | K23: THOTTINTE KIZHAKETHIL HOUSE, POST PUNTHALA, VIA KULANADA-689503 | L23: Unmatched — check | N23: 32551 | O23: Not Contacted | P23: Unassigned
A24: 21 | B24: 172 | C24: RAVINDRAN K.V. | D24: L | E24: 17319 | F24: =IFERROR(DATEDIF(E24,TODAY(),"Y"),"") -> 79 | G24: 0504554410 | H24: 497800071 | I24: ravindrankv48@yahoo.com | J24: Sharjah | K24: POST EDAT, VIA PAYYANNOOR, KANNUR DISTRICT, KERALA | L24: Kannur | M24: O+ | N24: 32540 | O24: Not Contacted | P24: Unassigned
A25: 22 | B25: 178 | C25: TEL (O): 06 5588888 | D25: EXT | E25: 26383 | F25: =IFERROR(DATEDIF(E25,TODAY(),"Y"),"") -> 54 | G25: 0505178700 | H25: 8943804638 | I25: aslamakattil@yahoo.com | K25: ANDIKATTIL HOUSE, MANNENGODE POST, PALAKKAD DT, EKRALA | L25: Palakkad | M25: O+ | N25: 40607 | O25: Not Contacted | P25: Unassigned
A26: 23 | B26: 194 | C26: KOLAVAYAL HASSAN | D26: L | E26: 19467 | F26: =IFERROR(DATEDIF(E26,TODAY(),"Y"),"") -> 73 | G26: 0506324975 | J26: Sharjah | K26: MONOKOTH KOTHIL HOUSE, KANHANGAD, KASARGOD DISTRICT | L26: Kasaragod | N26: 32555 | O26: Not Contacted | P26: Unassigned
A27: 24 | B27: 198 | C27: MATHEW THOMAS | D27: L | E27: 21692 | F27: =IFERROR(DATEDIF(E27,TODAY(),"Y"),"") -> 67 | G27: 0506797491 | I27: mathewtc@hotmail.com | J27: Ajman | K27: CHENGANDAYIL HOUSE, PONGA POST, VIA THEKKEKARA, ALLEPPEY, 762050 | L27: Alappuzha | M27: O+ | N27: 32558 | O27: Not Contacted | P27: Unassigned
A28: 25 | B28: 199 | C28: JACOB KURIEN .K | D28: L | E28: 19271 | F28: =IFERROR(DATEDIF(E28,TODAY(),"Y"),"") -> 73 | G28: 0555555836 | I28: jkk1504@gmail.com | J28: Ajman | K28: PALATHUMTHALAKKAL, THIRPPARAPU, KULASEKHARAM, KANYAKUMARY | L28: Unmatched — check | N28: 30737 | O28: Not Contacted | P28: Unassigned
A29: 26 | B29: 207 | C29: MADHAVAN THACHANGAD | D29: L | E29: 21404 | F29: =IFERROR(DATEDIF(E29,TODAY(),"Y"),"") -> 68 | G29: 0504580399 | I29: madhavan.kodorban@ricoh-europe.com | J29: Dubai | K29: THACHANGAD HOUSE, POST PANAYAL, VIA BEKAL, KASARGOD DISTRICT | L29: Kasaragod | N29: 32557 | O29: Not Contacted | P29: Unassigned
A30: 27 | B30: 226 | C30: P.M.JOSE | D30: L | E30: 19157 | F30: =IFERROR(DATEDIF(E30,TODAY(),"Y"),"") -> 74 | G30: 0506464569 | H30: 475712017 | I30: seasonpllc@gmail.com | J30: Sharjah | K30: PLAMMOOTTIL HOUSE, KULANADA POST, PANDALAM, PATHANAMTHITTA DISTRICT | L30: Pathanamthitta | N30: 32552 | O30: Not Contacted | P30: Unassigned
A31: 28 | B31: 227 | C31: P.C.SIMON | D31: L | E31: 18033 | F31: =IFERROR(DATEDIF(E31,TODAY(),"Y"),"") -> 77 | G31: 0502772525 | H31: 488574348 | I31: pcsimon@eim.ae | J31: Sharjah | K31: 28/564, EZHUTHACHAN NAGAR, NEAR, VADAKKECHIRA, TRICHUR-680001 | L31: Thrissur | M31: AB+ | N31: 30687 | O31: Not Contacted | P31: Unassigned
A32: 29 | B32: 233 | C32: RAJAN M K | D32: L | E32: 17676 | F32: =IFERROR(DATEDIF(E32,TODAY(),"Y"),"") -> 78 | G32: 0506464958 | H32: 474482089 | I32: mkrajan@eim.ae | J32: Sharjah | K32: MUKALIL HOUSE, CHITTAKODE, KARUVELIL POST, EZHUKONE-691505 | L32: Unmatched — check | M32: O+ | N32: 31360 | O32: Not Contacted | P32: Unassigned
A33: 30 | B33: 235 | C33: JOHN MATHAI | D33: L | E33: 21682 | F33: =IFERROR(DATEDIF(E33,TODAY(),"Y"),"") -> 67 | G33: 0504811206 | I33: johnmcm@eim.ae | J33: Sharjah | K33: PAITAYIL DHANYA, FIRST MILE, PERINGALA-PO.,, KAYAMKULAM, ALLEPPEY DT,KERALA, 0091 9645455559 | L33: Alappuzha | M33: O | N33: 32557 | O33: Not Contacted | P33: Unassigned
A34: 31 | B34: 236 | C34: JALEEL T. M. A. | D34: L | E34: 21098 | F34: =IFERROR(DATEDIF(E34,TODAY(),"Y"),"") -> 68 | G34: 0508933479 | J34: Sharjah | K34: POST PALAPPETTY, VELIANKODE, MALAPPURAM DISTRICT-679579 | L34: Malappuram | N34: 30696 | O34: Not Contacted | P34: Unassigned
A35: 32 | B35: 239 | C35: HAMZA PUTHOOR | D35: L | E35: 21297 | F35: =IFERROR(DATEDIF(E35,TODAY(),"Y"),"") -> 68 | G35: 0554326086 | H35: 8089080139 | I35: puthoorhamza@gmail.com | J35: Sharjah | K35: BEKAL FORT POST, THUTTE,, KASARGOD DISTRICT, KERALA | L35: Kasaragod | N35: 32555 | O35: Not Contacted | P35: Unassigned
A36: 33 | B36: 253 | C36: TEL (O): 06 5325353 - | D36: EXT | E36: 26992 | F36: =IFERROR(DATEDIF(E36,TODAY(),"Y"),"") -> 52 | G36: 0506337813 | H36: 9447225499 | I36: okhaneef@yahoo.com | K36: AL HILAL, MUKKOOD P.O, RAVANESHWAR, PALLIKERE VIA KASARAGOD DT. | L36: Kasaragod | N36: 38520 | O36: Not Contacted | P36: Unassigned
A37: 34 | B37: 256 | C37: CHERIAN THOMAS | D37: L | E37: 22488 | F37: =IFERROR(DATEDIF(E37,TODAY(),"Y"),"") -> 65 | G37: 0506263398 | H37: 9961263635 | I37: regicheri@gmail.com | J37: Sharjah | K37: PEEDIKAYIL PLAMMOOTTIL, KOZHENCHERY, POST, PATHANAMTHITTA DISTRICT | L37: Pathanamthitta | M37: B+ | N37: 32555 | O37: Not Contacted | P37: Unassigned
A38: 35 | B38: 268 | C38: ABRAHAM KURIAN | D38: L | E38: 22799 | F38: =IFERROR(DATEDIF(E38,TODAY(),"Y"),"") -> 64 | G38: 0506360886 | H38: 4842642742 | I38: chirackalkurian@gmail.com | J38: Sharjah | K38: CHIRACKAL HOUSE, KOOVAPPADY POST, AYATHUPADY, PERUMBAVOOR VIA | L38: Ernakulam | N38: 30739 | O38: Not Contacted | P38: Unassigned
A39: 36 | B39: 275 | C39: R.P.MURALY | D39: L | E39: 21149 | F39: =IFERROR(DATEDIF(E39,TODAY(),"Y"),"") -> 68 | G39: 0506265615 | H39: 9048887537 | I39: muralyputhuvelil@gmail.com | J39: Dubai | K39: MURALEERAVAM PUTHUVELIL,MALLASSERY P.O.,, PRAMADOM,VELAN KADAVU, PATHANAMTHITTA. | L39: Pathanamthitta | M39: B+ | N39: 30709 | O39: Not Contacted | P39: Unassigned
A40: 37 | B40: 281 | C40: M.HARIDAS | D40: L | E40: 20317 | F40: =IFERROR(DATEDIF(E40,TODAY(),"Y"),"") -> 70 | G40: 0555548916 | H40: 4942451903 | I40: haridas_melepat@hotmail.com | J40: Ajman | K40: MELEPAT HOUSE, POST VALIYORA, MALAPPURAM DISTRICT-676308,KERALA | L40: Malappuram | M40: O+ | N40: 32567 | O40: Not Contacted | P40: Unassigned
...

Sheet Lists
A1: Call Status | B1: Contact Method | C1: Assigned To | E1: District | G1: Emirate
A2: Not Contacted | B2: Phone Call | C2: Unassigned | E2: Alappuzha | G2: Sharjah
A3: Positive | B3: WhatsApp | C3: Volunteer 1 | E3: Ernakulam | G3: Dubai
A4: To Be Followed Up | B4: In Person | C4: Volunteer 2 | E4: Idukki | G4: Ajman
A5: Undecided | B5: Email | C5: Volunteer 3 | E5: Kannur | G5: Abu Dhabi
A6: Negative | B6: Through Referral | C6: Volunteer 4 | E6: Kasaragod | G6: Umm Al Quwain
A7: Unreachable | C7: Volunteer 5 | E7: Kollam | G7: Ras Al Khaimah
A8: Not Eligible / Inactive | C8: Volunteer 6 | E8: Kottayam | G8: Fujairah
C9: Volunteer 7 | E9: Kozhikode
C10: Volunteer 8 | E10: Malappuram
A11: Rename "Volunteer 1…12" in column C to your actual callers — the drop-down and the Team sheet follow automatically. | C11: Volunteer 9 | E11: Palakkad
C12: Volunteer 10 | E12: Pathanamthitta
C13: Volunteer 11 | E13: Thiruvananthapuram
C14: Volunteer 12 | E14: Thrissur
E15: Wayanad
E16: Outside Kerala
E17: Unmatched — check
